<?xml version="1.0" ?>
<!-- =================================================================================== -->
<!-- |    This document was autogenerated by xacro from gripper6dof.xacro              | -->
<!-- |    EDITING THIS FILE BY HAND IS NOT RECOMMENDED                                 | -->
<!-- =================================================================================== -->
<robot name="gripper">
  <link name="arm1_base"/>
  <link name="arm1_link1">
    <visual>
      <origin rpy="0 0 0" xyz="0 0 0.0275"/>
      <geometry>
        <cylinder length="0.055" radius="0.01"/>
      </geometry>
    </visual>
    <collision>
      <origin rpy="0 0 0" xyz="0 0 0.0275"/>
      <geometry>
        <cylinder length="0.055" radius="0.01"/>
      </geometry>
    </collision>
    <inertial>
      <origin rpy="0 0 0" xyz="0 0 0.0275"/>
      <mass value="0.1"/>
      <inertia ixx="2.770833333333333e-05" ixy="0.0" ixz="0.0" iyy="2.770833333333333e-05" iyz="0.0" izz="0.00015125000000000002"/>
    </inertial>
  </link>
  <link name="arm1_link2">
    <visual>
      <origin rpy="0 0 0" xyz="0 0 0.02"/>
      <geometry>
        <cylinder length="0.04" radius="0.01"/>
      </geometry>
    </visual>
    <collision>
      <origin rpy="0 0 0" xyz="0 0 0.02"/>
      <geometry>
        <cylinder length="0.04" radius="0.01"/>
      </geometry>
    </collision>
    <inertial>
      <origin rpy="0 0 0" xyz="0 0 0.02"/>
      <mass value="0.1"/>
      <inertia ixx="1.5833333333333333e-05" ixy="0.0" ixz="0.0" iyy="1.5833333333333333e-05" iyz="0.0" izz="8e-05"/>
    </inertial>
  </link>
  <link name="arm1_link3">
    <visual>
      <origin rpy="0 0 0" xyz="0 0 0.0225"/>
      <geometry>
        <cylinder length="0.045" radius="0.01"/>
      </geometry>
    </visual>
    <collision>
      <origin rpy="0 0 0" xyz="0 0 0.0225"/>
      <geometry>
        <cylinder length="0.045" radius="0.01"/>
      </geometry>
    </collision>
    <inertial>
      <origin rpy="0 0 0" xyz="0 0 0.0225"/>
      <mass value="0.1"/>
      <inertia ixx="1.9374999999999997e-05" ixy="0.0" ixz="0.0" iyy="1.9374999999999997e-05" iyz="0.0" izz="0.00010125"/>
    </inertial>
  </link>
  <joint name="arm1_joint1" type="revolute">
    <parent link="arm1_base"/>
    <child link="arm1_link1"/>
    <limit effort="30" lower="0" upper="3.141592653589793" velocity="1.0"/>
    <origin rpy="-1.5707963267948966 0 1.5707963267948966" xyz="-0.0235 -0.0325 0.12"/>
    <axis xyz="1 0 0"/>
  </joint>
  <joint name="arm1_joint2" type="revolute">
    <parent link="arm1_link1"/>
    <child link="arm1_link2"/>
    <limit effort="30" lower="0" upper="3.141592653589793" velocity="1.0"/>
    <origin rpy="0 0 0" xyz="0 0 0.055"/>
    <axis xyz="1 0 0"/>
  </joint>
  <joint name="arm1_joint3" type="revolute">
    <parent link="arm1_link2"/>
    <child link="arm1_link3"/>
    <limit effort="30" lower="0" upper="3.141592653589793" velocity="1.0"/>
    <origin rpy="0 0 0" xyz="0 0 0.04"/>
    <axis xyz="1 0 0"/>
  </joint>
  <link name="arm2_base"/>
  <link name="arm2_link1">
    <visual>
      <origin rpy="0 0 0" xyz="0 0 0.0275"/>
      <geometry>
        <cylinder length="0.055" radius="0.01"/>
      </geometry>
    </visual>
    <collision>
      <origin rpy="0 0 0" xyz="0 0 0.0275"/>
      <geometry>
        <cylinder length="0.055" radius="0.01"/>
      </geometry>
    </collision>
    <inertial>
      <origin rpy="0 0 0" xyz="0 0 0.0275"/>
      <mass value="0.1"/>
      <inertia ixx="2.770833333333333e-05" ixy="0.0" ixz="0.0" iyy="2.770833333333333e-05" iyz="0.0" izz="0.00015125000000000002"/>
    </inertial>
  </link>
  <link name="arm2_link2">
    <visual>
      <origin rpy="0 0 0" xyz="0 0 0.02"/>
      <geometry>
        <cylinder length="0.04" radius="0.01"/>
      </geometry>
    </visual>
    <collision>
      <origin rpy="0 0 0" xyz="0 0 0.02"/>
      <geometry>
        <cylinder length="0.04" radius="0.01"/>
      </geometry>
    </collision>
    <inertial>
      <origin rpy="0 0 0" xyz="0 0 0.02"/>
      <mass value="0.1"/>
      <inertia ixx="1.5833333333333333e-05" ixy="0.0" ixz="0.0" iyy="1.5833333333333333e-05" iyz="0.0" izz="8e-05"/>
    </inertial>
  </link>
  <link name="arm2_link3">
    <visual>
      <origin rpy="0 0 0" xyz="0 0 0.0225"/>
      <geometry>
        <cylinder length="0.045" radius="0.01"/>
      </geometry>
    </visual>
    <collision>
      <origin rpy="0 0 0" xyz="0 0 0.0225"/>
      <geometry>
        <cylinder length="0.045" radius="0.01"/>
      </geometry>
    </collision>
    <inertial>
      <origin rpy="0 0 0" xyz="0 0 0.0225"/>
      <mass value="0.1"/>
      <inertia ixx="1.9374999999999997e-05" ixy="0.0" ixz="0.0" iyy="1.9374999999999997e-05" iyz="0.0" izz="0.00010125"/>
    </inertial>
  </link>
  <joint name="arm2_joint1" type="revolute">
    <parent link="arm2_base"/>
    <child link="arm2_link1"/>
    <limit effort="30" lower="0" upper="3.141592653589793" velocity="1.0"/>
    <origin rpy="-1.5707963267948966 0 -1.5707963267948966" xyz="0.0235  0.0              0.12"/>
    <axis xyz="1 0 0"/>
  </joint>
  <joint name="arm2_joint2" type="revolute">
    <parent link="arm2_link1"/>
    <child link="arm2_link2"/>
    <limit effort="30" lower="0" upper="3.141592653589793" velocity="1.0"/>
    <origin rpy="0 0 0" xyz="0 0 0.055"/>
    <axis xyz="1 0 0"/>
  </joint>
  <joint name="arm2_joint3" type="revolute">
    <parent link="arm2_link2"/>
    <child link="arm2_link3"/>
    <limit effort="30" lower="0" upper="3.141592653589793" velocity="1.0"/>
    <origin rpy="0 0 0" xyz="0 0 0.04"/>
    <axis xyz="1 0 0"/>
  </joint>
  <link name="arm3_base"/>
  <link name="arm3_link1">
    <visual>
      <origin rpy="0 0 0" xyz="0 0 0.0275"/>
      <geometry>
        <cylinder length="0.055" radius="0.01"/>
      </geometry>
    </visual>
    <collision>
      <origin rpy="0 0 0" xyz="0 0 0.0275"/>
      <geometry>
        <cylinder length="0.055" radius="0.01"/>
      </geometry>
    </collision>
    <inertial>
      <origin rpy="0 0 0" xyz="0 0 0.0275"/>
      <mass value="0.1"/>
      <inertia ixx="2.770833333333333e-05" ixy="0.0" ixz="0.0" iyy="2.770833333333333e-05" iyz="0.0" izz="0.00015125000000000002"/>
    </inertial>
  </link>
  <link name="arm3_link2">
    <visual>
      <origin rpy="0 0 0" xyz="0 0 0.02"/>
      <geometry>
        <cylinder length="0.04" radius="0.01"/>
      </geometry>
    </visual>
    <collision>
      <origin rpy="0 0 0" xyz="0 0 0.02"/>
      <geometry>
        <cylinder length="0.04" radius="0.01"/>
      </geometry>
    </collision>
    <inertial>
      <origin rpy="0 0 0" xyz="0 0 0.02"/>
      <mass value="0.1"/>
      <inertia ixx="1.5833333333333333e-05" ixy="0.0" ixz="0.0" iyy="1.5833333333333333e-05" iyz="0.0" izz="8e-05"/>
    </inertial>
  </link>
  <link name="arm3_link3">
    <visual>
      <origin rpy="0 0 0" xyz="0 0 0.0225"/>
      <geometry>
        <cylinder length="0.045" radius="0.01"/>
      </geometry>
    </visual>
    <collision>
      <origin rpy="0 0 0" xyz="0 0 0.0225"/>
      <geometry>
        <cylinder length="0.045" radius="0.01"/>
      </geometry>
    </collision>
    <inertial>
      <origin rpy="0 0 0" xyz="0 0 0.0225"/>
      <mass value="0.1"/>
      <inertia ixx="1.9374999999999997e-05" ixy="0.0" ixz="0.0" iyy="1.9374999999999997e-05" iyz="0.0" izz="0.00010125"/>
    </inertial>
  </link>
  <joint name="arm3_joint1" type="revolute">
    <parent link="arm3_base"/>
    <child link="arm3_link1"/>
    <limit effort="30" lower="0" upper="3.141592653589793" velocity="1.0"/>
    <origin rpy="-1.5707963267948966 0 1.5707963267948966" xyz="-0.0235 0.024000000000000004 0.12"/>
    <axis xyz="1 0 0"/>
  </joint>
  <joint name="arm3_joint2" type="revolute">
    <parent link="arm3_link1"/>
    <child link="arm3_link2"/>
    <limit effort="30" lower="0" upper="3.141592653589793" velocity="1.0"/>
    <origin rpy="0 0 0" xyz="0 0 0.055"/>
    <axis xyz="1 0 0"/>
  </joint>
  <joint name="arm3_joint3" type="revolute">
    <parent link="arm3_link2"/>
    <child link="arm3_link3"/>
    <limit effort="30" lower="0" upper="3.141592653589793" velocity="1.0"/>
    <origin rpy="0 0 0" xyz="0 0 0.04"/>
    <axis xyz="1 0 0"/>
  </joint>
  <link name="drone">
    <visual>
      <origin rpy="0 0 0" xyz="0 0 0.0"/>
      <geometry>
        <box size="0.075 0.1 0.08"/>
      </geometry>
    </visual>
    <visual>
      <origin rpy="0 0 0" xyz="0 0 -0.06"/>
      <geometry>
        <box size="0.25 0.225 0.04"/>
      </geometry>
    </visual>
    <collision>
      <origin rpy="0 0 0" xyz="0 0 0.0"/>
      <geometry>
        <box size="0.075 0.1 0.08"/>
      </geometry>
    </collision>
    <collision>
      <origin rpy="0 0 0" xyz="0 0 -0.06"/>
      <geometry>
        <box size="0.25 0.225 0.04"/>
      </geometry>
    </collision>
    <inertial>
      <origin rpy="0 0 0" xyz="0 0 0"/>
      <mass value="1.0"/>
      <inertia ixx="0.004752083333333334" ixy="0.0" ixz="0.0" iyy="0.005741666666666667" iyz="0.0" izz="0.009427083333333332"/>
    </inertial>
  </link>
  <!--<joint name="droneFixture" type="fixed">
        <parent link="drone"/>
        <child link="base"/>
    </joint>-->
  <joint name="arm1_fix" type="fixed">
    <origin rpy="0 0 0" xyz="0 0 -0.08"/>
    <parent link="drone"/>
    <child link="arm1_base"/>
  </joint>
  <joint name="arm2_fix" type="fixed">
    <origin rpy="0 0 0" xyz="0 0 -0.08"/>
    <parent link="drone"/>
    <child link="arm2_base"/>
  </joint>
  <joint name="arm3_fix" type="fixed">
    <origin rpy="0 0 0" xyz="0 0 -0.08"/>
    <parent link="drone"/>
    <child link="arm3_base"/>
  </joint>
</robot>
