<?xml version="1.0" ?>
<!-- =================================================================================== -->
<!-- |    This document was autogenerated by xacro from gripper.xacro                  | -->
<!-- |    EDITING THIS FILE BY HAND IS NOT RECOMMENDED                                 | -->
<!-- =================================================================================== -->
<robot name="gripper">
  <link name="arm1_base"/>
  <link name="arm1_link1">
    <visual>
      <origin rpy="0 0 0" xyz="0 0 0.0275"/>
      <geometry>
        <cylinder length="0.055" radius="0.01"/>
      </geometry>
    </visual>
    <collision>
      <origin rpy="0 0 0" xyz="0 0 0.0275"/>
      <geometry>
        <cylinder length="0.055" radius="0.01"/>
      </geometry>
    </collision>
    <inertial>
      <origin rpy="0 0 0" xyz="0 0 0.0275"/>
      <mass value="0.1"/>
      <inertia ixx="2.770833333333333e-05" ixy="0.0" ixz="0.0" iyy="2.770833333333333e-05" iyz="0.0" izz="0.00015125000000000002"/>
    </inertial>
  </link>
  <link name="arm1_link2">
    <visual>
      <origin rpy="0 0 0" xyz="0 0 0.02"/>
      <geometry>
        <cylinder length="0.04" radius="0.01"/>
      </geometry>
    </visual>
    <collision>
      <origin rpy="0 0 0" xyz="0 0 0.02"/>
      <geometry>
        <cylinder length="0.04" radius="0.01"/>
      </geometry>
    </collision>
    <inertial>
      <origin rpy="0 0 0" xyz="0 0 0.02"/>
      <mass value="0.1"/>
      <inertia ixx="1.5833333333333333e-05" ixy="0.0" ixz="0.0" iyy="1.5833333333333333e-05" iyz="0.0" izz="8e-05"/>
    </inertial>
  </link>
  <link name="arm1_link3">
    <visual>
      <origin rpy="0 0 0" xyz="0 0 0.0225"/>
      <geometry>
        <cylinder length="0.045" radius="0.01"/>
      </geometry>
    </visual>
    <collision>
      <origin rpy="0 0 0" xyz="0 0 0.0225"/>
      <geometry>
        <cylinder length="0.045" radius="0.01"/>
      </geometry>
    </collision>
    <inertial>
      <origin rpy="0 0 0" xyz="0 0 0.0225"/>
      <mass value="0.1"/>
      <inertia ixx="1.9374999999999997e-05" ixy="0.0" ixz="0.0" iyy="1.9374999999999997e-05" iyz="0.0" izz="0.00010125"/>
    </inertial>
  </link>
  <joint name="arm1_joint1" type="revolute">
    <parent link="arm1_base"/>
    <child link="arm1_link1"/>
    <limit effort="30" lower="0" upper="3.141592653589793" velocity="1.0"/>
    <origin rpy="-1.5707963267948966 0 1.5707963267948966" xyz="-0.0235 -0.0325 0.12"/>
    <axis xyz="1 0 0"/>
  </joint>
  <joint name="arm1_joint2" type="revolute">
    <parent link="arm1_link1"/>
    <child link="arm1_link2"/>
    <limit effort="30" lower="0" upper="3.141592653589793" velocity="1.0"/>
    <origin rpy="0 0 0" xyz="0 0 0.055"/>
    <axis xyz="1 0 0"/>
  </joint>
  <joint name="arm1_joint3" type="revolute">
    <parent link="arm1_link2"/>
    <child link="arm1_link3"/>
    <limit effort="30" lower="0" upper="3.141592653589793" velocity="1.0"/>
    <origin rpy="0 0 0" xyz="0 0 0.04"/>
    <axis xyz="1 0 0"/>
  </joint>
  <link name="arm2_base"/>
  <link name="arm2_link1">
    <visual>
      <origin rpy="0 0 0" xyz="0 0 0.0275"/>
      <geometry>
        <cylinder length="0.055" radius="0.01"/>
      </geometry>
    </visual>
    <collision>
      <origin rpy="0 0 0" xyz="0 0 0.0275"/>
      <geometry>
        <cylinder length="0.055" radius="0.01"/>
      </geometry>
    </collision>
    <inertial>
      <origin rpy="0 0 0" xyz="0 0 0.0275"/>
      <mass value="0.1"/>
      <inertia ixx="2.770833333333333e-05" ixy="0.0" ixz="0.0" iyy="2.770833333333333e-05" iyz="0.0" izz="0.00015125000000000002"/>
    </inertial>
  </link>
  <link name="arm2_link2">
    <visual>
      <origin rpy="0 0 0" xyz="0 0 0.02"/>
      <geometry>
        <cylinder length="0.04" radius="0.01"/>
      </geometry>
    </visual>
    <collision>
      <origin rpy="0 0 0" xyz="0 0 0.02"/>
      <geometry>
        <cylinder length="0.04" radius="0.01"/>
      </geometry>
    </collision>
    <inertial>
      <origin rpy="0 0 0" xyz="0 0 0.02"/>
      <mass value="0.1"/>
      <inertia ixx="1.5833333333333333e-05" ixy="0.0" ixz="0.0" iyy="1.5833333333333333e-05" iyz="0.0" izz="8e-05"/>
    </inertial>
  </link>
  <link name="arm2_link3">
    <visual>
      <origin rpy="0 0 0" xyz="0 0 0.0225"/>
      <geometry>
        <cylinder length="0.045" radius="0.01"/>
      </geometry>
    </visual>
    <collision>
      <origin rpy="0 0 0" xyz="0 0 0.0225"/>
      <geometry>
        <cylinder length="0.045" radius="0.01"/>
      </geometry>
    </collision>
    <inertial>
      <origin rpy="0 0 0" xyz="0 0 0.0225"/>
      <mass value="0.1"/>
      <inertia ixx="1.9374999999999997e-05" ixy="0.0" ixz="0.0" iyy="1.9374999999999997e-05" iyz="0.0" izz="0.00010125"/>
    </inertial>
  </link>
  <joint name="arm2_joint1" type="revolute">
    <parent link="arm2_base"/>
    <child link="arm2_link1"/>
    <limit effort="30" lower="0" upper="3.141592653589793" velocity="1.0"/>
    <origin rpy="-1.5707963267948966 0 -1.5707963267948966" xyz="0.0235  0.0              0.12"/>
    <axis xyz="1 0 0"/>
  </joint>
  <joint name="arm2_joint2" type="revolute">
    <parent link="arm2_link1"/>
    <child link="arm2_link2"/>
    <limit effort="30" lower="0" upper="3.141592653589793" velocity="1.0"/>
    <origin rpy="0 0 0" xyz="0 0 0.055"/>
    <axis xyz="1 0 0"/>
  </joint>
  <joint name="arm2_joint3" type="revolute">
    <parent link="arm2_link2"/>
    <child link="arm2_link3"/>
    <limit effort="30" lower="0" upper="3.141592653589793" velocity="1.0"/>
    <origin rpy="0 0 0" xyz="0 0 0.04"/>
    <axis xyz="1 0 0"/>
  </joint>
  <link name="arm3_base"/>
  <link name="arm3_link1">
    <visual>
      <origin rpy="0 0 0" xyz="0 0 0.0275"/>
      <geometry>
        <cylinder length="0.055" radius="0.01"/>
      </geometry>
    </visual>
    <collision>
      <origin rpy="0 0 0" xyz="0 0 0.0275"/>
      <geometry>
        <cylinder length="0.055" radius="0.01"/>
      </geometry>
    </collision>
    <inertial>
      <origin rpy="0 0 0" xyz="0 0 0.0275"/>
      <mass value="0.1"/>
      <inertia ixx="2.770833333333333e-05" ixy="0.0" ixz="0.0" iyy="2.770833333333333e-05" iyz="0.0" izz="0.00015125000000000002"/>
    </inertial>
  </link>
  <link name="arm3_link2">
    <visual>
      <origin rpy="0 0 0" xyz="0 0 0.02"/>
      <geometry>
        <cylinder length="0.04" radius="0.01"/>
      </geometry>
    </visual>
    <collision>
      <origin rpy="0 0 0" xyz="0 0 0.02"/>
      <geometry>
        <cylinder length="0.04" radius="0.01"/>
      </geometry>
    </collision>
    <inertial>
      <origin rpy="0 0 0" xyz="0 0 0.02"/>
      <mass value="0.1"/>
      <inertia ixx="1.5833333333333333e-05" ixy="0.0" ixz="0.0" iyy="1.5833333333333333e-05" iyz="0.0" izz="8e-05"/>
    </inertial>
  </link>
  <link name="arm3_link3">
    <visual>
      <origin rpy="0 0 0" xyz="0 0 0.0225"/>
      <geometry>
        <cylinder length="0.045" radius="0.01"/>
      </geometry>
    </visual>
    <collision>
      <origin rpy="0 0 0" xyz="0 0 0.0225"/>
      <geometry>
        <cylinder length="0.045" radius="0.01"/>
      </geometry>
    </collision>
    <inertial>
      <origin rpy="0 0 0" xyz="0 0 0.0225"/>
      <mass value="0.1"/>
      <inertia ixx="1.9374999999999997e-05" ixy="0.0" ixz="0.0" iyy="1.9374999999999997e-05" iyz="0.0" izz="0.00010125"/>
    </inertial>
  </link>
  <joint name="arm3_joint1" type="revolute">
    <parent link="arm3_base"/>
    <child link="arm3_link1"/>
    <limit effort="30" lower="0" upper="3.141592653589793" velocity="1.0"/>
    <origin rpy="-1.5707963267948966 0 1.5707963267948966" xyz="-0.0235 0.024000000000000004 0.12"/>
    <axis xyz="1 0 0"/>
  </joint>
  <joint name="arm3_joint2" type="revolute">
    <parent link="arm3_link1"/>
    <child link="arm3_link2"/>
    <limit effort="30" lower="0" upper="3.141592653589793" velocity="1.0"/>
    <origin rpy="0 0 0" xyz="0 0 0.055"/>
    <axis xyz="1 0 0"/>
  </joint>
  <joint name="arm3_joint3" type="revolute">
    <parent link="arm3_link2"/>
    <child link="arm3_link3"/>
    <limit effort="30" lower="0" upper="3.141592653589793" velocity="1.0"/>
    <origin rpy="0 0 0" xyz="0 0 0.04"/>
    <axis xyz="1 0 0"/>
  </joint>
  <!-- Optionally, add a base link or other structure to connect the arms -->
  <link name="world"/>
  <link name="p1"/>
  <link name="p2"/>
  <link name="p3"/>
  <link name="drone">
    <collision>
      <origin rpy="0 0 0" xyz="0 0 0.02"/>
      <geometry>
        <box size="0.25 0.225 0.04"/>
      </geometry>
    </collision>
  </link>
  <link name="base">
    <visual>
      <geometry>
        <box size="0.25 0.225 0.08"/>
      </geometry>
    </visual>
    <collision>
      <origin rpy="0 0 0" xyz="0 0 0.08"/>
      <geometry>
        <box size="0.075 0.1 0.08"/>
      </geometry>
    </collision>
    <inertial>
      <origin rpy="0 0 0" xyz="0 0 0"/>
      <mass value="1.0"/>
      <inertia ixx="0.004752083333333334" ixy="0.0" ixz="0.0" iyy="0.005741666666666667" iyz="0.0" izz="0.009427083333333332"/>
    </inertial>
  </link>
  <joint name="droneFixture" type="fixed">
    <parent link="drone"/>
    <child link="base"/>
  </joint>
  <joint name="x_pos" type="prismatic">
    <origin rpy="0 0 0" xyz="0 0 -0.16"/>
    <parent link="world"/>
    <child link="p1"/>
    <axis xyz="1 0 0"/>
    <limit effort="100" lower="-100" upper="100" velocity="100"/>
  </joint>
  <joint name="y_pos" type="prismatic">
    <parent link="p1"/>
    <child link="p2"/>
    <axis xyz="0 1 0"/>
    <limit effort="100" lower="-100" upper="100" velocity="100"/>
  </joint>
  <joint name="z_pos" type="prismatic">
    <parent link="p2"/>
    <child link="p3"/>
    <axis xyz="0 0 1"/>
    <limit effort="100" lower="-100" upper="100" velocity="100"/>
  </joint>
  <joint name="base_joint" type="continuous">
    <parent link="p3"/>
    <child link="drone"/>
    <axis xyz="0 0 1"/>
    <dynamics damping="100.0" friction="0.0"/>
  </joint>
  <joint name="arm1_fix" type="fixed">
    <parent link="base"/>
    <child link="arm1_base"/>
  </joint>
  <joint name="arm2_fix" type="fixed">
    <parent link="base"/>
    <child link="arm2_base"/>
  </joint>
  <joint name="arm3_fix" type="fixed">
    <parent link="base"/>
    <child link="arm3_base"/>
  </joint>
</robot>
